Workbook

Sheet Test Case
A1: ID | B1: UC | C1: Tiêu đề | D1: Loại | E1: Kỹ thuật | F1: Truy vết (UC Spec / API) | G1: Ưu tiên | H1: Pre-condition | I1: Dữ liệu test | J1: Expected result | K1: Actual result | L1: Pass/Fail | M1: Ảnh bằng chứng | N1: Ghi chú / giả định
A2: TC-01-01 | B2: UC01 | C2: Tạo order và gửi bếp thành công | D2: Happy path | E2: Functional (main flow) | F2: SD Tạo order (msg 2–25); api-contract §3 UC01 (POST /orders); UC01 main flow | G2: Cao | H2: Đã nạp lại schema.sql rồi seed.sql; đã đăng nhập phucvu01. ban-01 (B01) đang TRONG. | I2: banId = ban-01 (B01) mon-02 (Cà phê sữa) x2, ghi chú "ít đá" mon-04 (Trà đào) x1 | J2: HTTP 201, success=true. data: trangThai=DANG_PHUC_VU; tongTien = 2×30.000 + 40.000 = 100.000; isSynced=true; mỗi món có chiTietId, donGia đúng, trangThaiCheBien=CHO_PHA_CHE; ghi chú "ít đá" được lưu. Bàn chuyển DANG_PHUC_VU. CSDL có 1 don_hang và 2 chi_tiet_don tương ứng. | K2: HTTP 201, success=true. data: trangThai=DANG_PHUC_VU; tongTien = 2×30.000 + 40.000 = 100.000; isSynced=true; mỗi món có chiTietId, donGia đúng, trangThaiCheBien=CHO_PHA_CHE; ghi chú "ít đá" được lưu. Bàn chuyển DANG_PHUC_VU. CSDL có 1 don_hang và 2 chi_tiet_don tương ứng. | L2: Pass | M2: KQ-test\TC-01-01.png
A3: TC-01-02 | B3: UC01 | C3: Số lượng = 1 (biên dưới hợp lệ) | D3: Boundary | E3: BVA (biên dưới = 1) | F3: SD Tạo order (msg 2–25); api-contract §3 UC01 (POST /orders); BPC T3 (số lượng 1–99) | G3: Cao | H3: Đã nạp lại schema.sql rồi seed.sql; đã đăng nhập phucvu01. ban-01 (B01) đang TRONG. | I3: banId = ban-01 (B01); mon-02 (Cà phê sữa) soLuong = 1 | J3: HTTP 201; chi tiết món soLuong=1; tongTien = 30.000; bàn chuyển DANG_PHUC_VU. | K3: HTTP 201; chi tiết món soLuong=1; tongTien = 30.000; bàn chuyển DANG_PHUC_VU. | L3: Pass | M3: KQ-test\TC-01-02.png
A4: TC-01-03 | B4: UC01 | C4: Số lượng = 99 (biên trên hợp lệ) | D4: Boundary | E4: BVA (biên trên = 99) | F4: SD Tạo order (msg 2–25); api-contract §3 UC01 (POST /orders); BPC T3 (số lượng 1–99) | G4: Cao | H4: Đã nạp lại schema.sql rồi seed.sql; đã đăng nhập phucvu01. ban-01 (B01) đang TRONG. | I4: banId = ban-01 (B01); mon-02 (Cà phê sữa) soLuong = 99 | J4: HTTP 201; soLuong=99; tongTien = 99×30.000 = 2.970.000; bàn chuyển DANG_PHUC_VU. | K4: HTTP 201; soLuong=99; tongTien = 99×30.000 = 2.970.000; bàn chuyển DANG_PHUC_VU. | L4: Pass | M4: KQ-test\TC-01-03.png
A5: TC-01-04 | B5: UC01 | C5: Số lượng = 0 | D5: Negative | E5: EP (invalid class: số lượng < 1) | F5: SD Tạo order (msg 2–25); api-contract §3 UC01 (POST /orders); mã lỗi SO_LUONG_KHONG_HOP_LE | G5: Cao | H5: Đã nạp lại schema.sql rồi seed.sql; đã đăng nhập phucvu01. ban-01 (B01) đang TRONG. | I5: banId = ban-01 (B01); mon-02 (Cà phê sữa) soLuong = 0 | J5: Giao diện không cho gửi hoặc báo lỗi số lượng. API: HTTP 400, maLoi=SO_LUONG_KHONG_HOP_LE. Không tạo don_hang; bàn vẫn TRONG. | K5: Giao diện chỉ có cho số lượng 1 ấn dấu - số lượng không bị thay đổi | L5: Pass
A6: TC-01-05 | B6: UC01 | C6: Số lượng âm (-1) | D6: Negative | E6: EP (invalid class: số lượng âm) | F6: SD Tạo order (msg 2–25); api-contract §3 UC01 (POST /orders); mã lỗi SO_LUONG_KHONG_HOP_LE | G6: Cao | H6: Đã nạp lại schema.sql rồi seed.sql; đã đăng nhập phucvu01. ban-01 (B01) đang TRONG. | I6: banId = ban-01 (B01); mon-02 (Cà phê sữa) soLuong = -1 | J6: Giao diện không cho gửi hoặc báo lỗi. API: HTTP 400, maLoi=SO_LUONG_KHONG_HOP_LE. Không tạo don_hang; bàn vẫn TRONG. | K6: Giao diện chỉ có cho số lượng 1 ấn dấu - số lượng không bị thay đổi | L6: Pass
A7: TC-01-06 | B7: UC01 | C7: Số lượng = 100 (vượt biên trên), kiểm tra ở server | D7: Boundary | E7: BVA (ngay trên biên 99) | F7: SD Tạo order (msg 2–25); api-contract §3 UC01 (POST /orders); BPC T3 (từ chối ở server, không chỉ giao diện) | G7: Cao | H7: Đã nạp lại schema.sql rồi seed.sql; đã đăng nhập phucvu01. ban-01 (B01) đang TRONG. | I7: banId = ban-01 (B01); mon-02 (Cà phê sữa) soLuong = 100 | J7: API: HTTP 400, maLoi=SO_LUONG_KHONG_HOP_LE. Không tạo don_hang; bàn vẫn TRONG. | K7: Giao diện chỉ có cho số lượng 100 ấn dấu + số lượng không bị thay đổi | L7: Pass
A8: TC-01-07 | B8: UC01 | C8: Gọi món đã hết nguyên liệu (TAM_HET) | D8: Alternative flow | E8: Black-box theo UC Spec (EF: món hết nguyên liệu) | F8: SD Tạo order (msg 2–25); api-contract §3 UC01 (POST /orders); BPC T3, H3 | G8: Cao | H8: Đã nạp lại schema.sql rồi seed.sql; đã đăng nhập phucvu01. ban-01 (B01) đang TRONG; mon-03 (Bạc xỉu) ở trạng thái TAM_HET. | I8: banId = ban-01 (B01); mon-03 (Bạc xỉu) soLuong = 1 | J8: Giao diện: món hiện xám, không chọn được. API: HTTP 409, maLoi=MON_TAM_HET, message dạng "Món … đã hết nguyên liệu" (có tên món). Không tạo đơn; bàn vẫn TRONG. | K8: Giao diện: món hiện xám, không chọn được. message: bạc xĩu đã hết nguyên liệu và bàn vẫn trống | L8: Pass | M8: KQ-test\TC-01-07.png | N8: Cần món TAM_HET trong seed [X05].
A9: TC-01-08 | B9: UC01 | C9: Gọi món ở bàn đang CAN_DON | D9: Alternative flow | E9: Black-box theo UC Spec (EF: bàn không hợp lệ) | F9: SD Tạo order (msg 2–25); api-contract §3 UC01 (POST /orders); BPC T3, H3 | G9: Cao | H9: Đã nạp lại schema.sql rồi seed.sql; đã đăng nhập phucvu01. ban-05 (B05) đang CAN_DON. | I9: banId = ban-05 (B05); mon-02 (Cà phê sữa) soLuong = 1 | J9: Giao diện: bàn CAN_DON không bấm gọi món được. API: HTTP 409, maLoi=BAN_CAN_DON. Không tạo đơn; trạng thái bàn giữ nguyên. | K9: bàn cân dọn không gọi món được, hiện message cần dọn bàn | L9: Pass | M9: KQ-test\TC-01-08.png
A10: TC-01-09 | B10: UC01 | C10: Tạo order mới cho bàn đang có đơn | D10: Alternative flow | E10: Black-box theo UC Spec (đề xuất contract §4) | F10: api-contract §4 điểm 1 (BAN_DA_CO_DON) | G10: Trung | H10: Đã nạp lại schema.sql rồi seed.sql; đã đăng nhập phucvu01. ban-03 (B03) đang DANG_PHUC_VU và đã có đơn dh-001. | I10: banId = ban-03 (B03); mon-02 (Cà phê sữa) soLuong = 1 | J10: HTTP 409, maLoi=BAN_DA_CO_DON. Không tạo đơn thứ hai; số don_hang của bàn vẫn là 1. | K10: Khi bàn đang phục vụ thì màn hình tạo hóa đơn chỉ có gọi thêm chứ không còn tạo thêm đơn nữa | L10: Pass | N10: Đề xuất của Tuấn trong contract, chưa chốt [X01]. Nếu chốt khác thì sửa Expected.
A11: TC-01-10 | B11: UC01 | C11: Gửi order khi giỏ hàng rỗng | D11: Negative | E11: EP (invalid class: danh sách món rỗng) | F11: SD Tạo order (msg 2–25); api-contract §3 UC01 (POST /orders); mã lỗi DS_MON_RONG | G11: Thấp | H11: Đã nạp lại schema.sql rồi seed.sql; đã đăng nhập phucvu01. ban-01 (B01) đang TRONG. | I11: banId = ban-01 (B01); dsMon = [] | J11: HTTP 400, maLoi=DS_MON_RONG. Không tạo đơn; bàn vẫn TRONG. | K11: Hệ thống báo lỗi chưa chọn món nào | L11: Pass | M11: KQ-test\TC-01-10.png
A12: TC-04-01 | B12: UC04 | C12: Gọi thêm món vào đơn đang phục vụ | D12: Happy path | E12: Functional (main flow) | F12: CD_CapNhat (themMon/suaMon/huyMon); api-contract §3 UC04 (POST /orders/:id/items) | G12: Cao | H12: Đã nạp lại schema.sql rồi seed.sql; đã đăng nhập phucvu01; đơn dh-001 của ban-03 (B03) đang DANG_PHUC_VU, tổng 85.000: ct-001 (Cà phê sữa x2, DANG_LAM), ct-002 (Cà phê đen x1, CHO_PHA_CHE). Tổng tiền hiện tại = 85.000. | I12: mon-04 (Trà đào) x1, ghi chú "không đường" | J12: HTTP 200. dsMon gồm các món cũ (giữ nguyên trạng thái) và 1 món mới CHO_PHA_CHE; tongTien = 85.000 + 40.000 = 125.000. Chỉ món mới được gửi xuống bếp (bếp không có bản sao của món cũ). | K12: HTTP 200. dsMon gồm các món cũ (giữ nguyên trạng thái) và 1 món mới CHO_PHA_CHE; tongTien = 85.000 + 40.000 = 125.000. Chỉ món mới được gửi xuống bếp (bếp không có bản sao của món cũ). | L12: pass | M12: KQ-test\TC-04-01.png
A13: TC-04-02 | B13: UC04 | C13: Sửa số lượng món đang CHO_PHA_CHE | D13: Happy path | E13: Functional (main flow) | F13: CD_CapNhat (themMon/suaMon/huyMon); api-contract §3 UC04 (PATCH /orders/:id/items/:chiTietId) | G13: Cao | H13: Đã nạp lại schema.sql rồi seed.sql; đã đăng nhập phucvu01; đơn dh-001 của ban-03 (B03) đang DANG_PHUC_VU, tổng 85.000: ct-001 (Cà phê sữa x2, DANG_LAM), ct-002 (Cà phê đen x1, CHO_PHA_CHE). | I13: ct-002 (Cà phê đen): số lượng 1 → 3 | J13: HTTP 200. soLuong=3; tongTien = 85.000 + 2×25.000 = 135.000; món vẫn CHO_PHA_CHE. | K13: HTTP 200. soLuong=3; tongTien = 85.000 + 4×40.000 = 245000; món vẫn CHO_PHA_CHE. | L13: Pass | M13: KQ-test\TC-04-02.png
A14: TC-04-03 | B14: UC04 | C14: Hủy món đang CHO_PHA_CHE | D14: Happy path | E14: Functional (main flow) | F14: CD_CapNhat (themMon/suaMon/huyMon); api-contract §3 UC04 (DELETE /orders/:id/items/:chiTietId) | G14: Cao | H14: Đã nạp lại schema.sql rồi seed.sql; đã đăng nhập phucvu01; đơn dh-001 của ban-03 (B03) đang DANG_PHUC_VU, tổng 85.000: ct-001 (Cà phê sữa x2, DANG_LAM), ct-002 (Cà phê đen x1, CHO_PHA_CHE). | I14: ct-002 | J14: HTTP 200. ct-002 chuyển DA_HUY; tongTien = 85.000 − 25.000 = 60.000 (món hủy không tính); món không còn hiện trên màn Bếp. | K14: HTTP 200. ct-002 chuyển DA_HUY; tongTien = 85.000 − 25.000 = 60.000 (món hủy không tính); món không còn hiện trên màn Bếp. | L14: Pass | M14: KQ-test\TC-04-03.png
A15: TC-04-04 | B15: UC04 | C15: Sửa số lượng = 1 (biên dưới hợp lệ) | D15: Boundary | E15: BVA (biên dưới = 1) | F15: CD_CapNhat (themMon/suaMon/huyMon); api-contract §3 UC04; BPC T4 | G15: Cao | H15: Đã nạp lại schema.sql rồi seed.sql; đã đăng nhập phucvu01; đơn dh-001 của ban-03 (B03) đang DANG_PHUC_VU, tổng 85.000: ct-001 (Cà phê sữa x2, DANG_LAM), ct-002 (Cà phê đen x1, CHO_PHA_CHE). | I15: ct-002: sửa 1 → 2 (chuẩn bị), sau đó 2 → 1 | J15: Sau bước 3: HTTP 200; soLuong=1; tongTien = 85.000. | K15: Sau bước 3: HTTP 200; soLuong=1; tongTien = 85.000. | L15: Pass
A16: TC-04-05 | B16: UC04 | C16: Sửa số lượng = 99 (biên trên hợp lệ) | D16: Boundary | E16: BVA (biên trên = 99) | F16: CD_CapNhat (themMon/suaMon/huyMon); api-contract §3 UC04; BPC T4 | G16: Cao | H16: Đã nạp lại schema.sql rồi seed.sql; đã đăng nhập phucvu01; đơn dh-001 của ban-03 (B03) đang DANG_PHUC_VU, tổng 85.000: ct-001 (Cà phê sữa x2, DANG_LAM), ct-002 (Cà phê đen x1, CHO_PHA_CHE). | I16: ct-002: số lượng → 99 | J16: HTTP 200. soLuong=99; tongTien = 60.000 + 99×25.000 = 2.535.000. | K16: HTTP 200. soLuong=99; tongTien = 60.000 + 99×25.000 = 2.535.000. | L16: Pass
A17: TC-04-06 | B17: UC04 | C17: Sửa số lượng = 0 | D17: Negative | E17: EP (invalid class: số lượng < 1) | F17: CD_CapNhat (themMon/suaMon/huyMon); api-contract §3 UC04; mã lỗi SO_LUONG_KHONG_HOP_LE | G17: Cao | H17: Đã nạp lại schema.sql rồi seed.sql; đã đăng nhập phucvu01; đơn dh-001 của ban-03 (B03) đang DANG_PHUC_VU, tổng 85.000: ct-001 (Cà phê sữa x2, DANG_LAM), ct-002 (Cà phê đen x1, CHO_PHA_CHE). | I17: ct-002: soLuong = 0 | J17: API: HTTP 400, maLoi=SO_LUONG_KHONG_HOP_LE. Số lượng và tongTien không đổi. | K17: Hệ thống không cho chỉnh số lượng về 0 | L17: Pass
A18: TC-04-07 | B18: UC04 | C18: Sửa số lượng = 100 (vượt biên trên) | D18: Boundary | E18: BVA (ngay trên biên 99) | F18: CD_CapNhat (themMon/suaMon/huyMon); api-contract §3 UC04; mã lỗi SO_LUONG_KHONG_HOP_LE | G18: Cao | H18: Đã nạp lại schema.sql rồi seed.sql; đã đăng nhập phucvu01; đơn dh-001 của ban-03 (B03) đang DANG_PHUC_VU, tổng 85.000: ct-001 (Cà phê sữa x2, DANG_LAM), ct-002 (Cà phê đen x1, CHO_PHA_CHE). | I18: ct-002: soLuong = 100 | J18: HTTP 400, maLoi=SO_LUONG_KHONG_HOP_LE. Số lượng và tongTien không đổi. | K18: Hệ thống không cho chỉnh số lượng về 100 | L18: Pass
A19: TC-04-08 | B19: UC04 | C19: Hủy món đang DANG_LAM bị chặn | D19: Alternative flow | E19: Black-box theo UC Spec (EF: món đã chế biến) | F19: CD_CapNhat (themMon/suaMon/huyMon); api-contract §3 UC04; BPC T4, H3 (ẩn nút hủy) | G19: Cao | H19: Đã nạp lại schema.sql rồi seed.sql; đã đăng nhập phucvu01; đơn dh-001 của ban-03 (B03) đang DANG_PHUC_VU, tổng 85.000: ct-001 (Cà phê sữa x2, DANG_LAM), ct-002 (Cà phê đen x1, CHO_PHA_CHE). ct-001 đang DANG_LAM. | I19: ct-001 | J19: Giao diện ẩn nút "Hủy" với món DANG_LAM. API: HTTP 409, maLoi=MON_DA_CHE_BIEN, message rõ ràng. Món vẫn DANG_LAM; tongTien không đổi. | K19: hệ thống không hiện nút hủy với món đang làm | L19: Pass | N19: [X05]
A20: TC-04-09 | B20: UC04 | C20: Sửa số lượng món đang DANG_LAM bị chặn | D20: Alternative flow | E20: Black-box theo UC Spec (EF: món đã chế biến) | F20: CD_CapNhat (themMon/suaMon/huyMon); api-contract §3 UC04; BPC T4 | G20: Trung | H20: Đã nạp lại schema.sql rồi seed.sql; đã đăng nhập phucvu01; đơn dh-001 của ban-03 (B03) đang DANG_PHUC_VU, tổng 85.000: ct-001 (Cà phê sữa x2, DANG_LAM), ct-002 (Cà phê đen x1, CHO_PHA_CHE). ct-001 đang DANG_LAM. | I20: ct-001: soLuong = 2 | J20: HTTP 409, maLoi=MON_DA_CHE_BIEN. Số lượng và tongTien không đổi. | K20: Màn hình không cho phép thay đổi số lượng khi món đang làm | L20: Pass | M20: KQ-test\TC-04-09.png
A21: TC-04-10 | B21: UC04 | C21: Sửa và hủy món đã DA_XONG bị chặn | D21: Alternative flow | E21: Black-box theo UC Spec (EF: món đã chế biến) | F21: CD_CapNhat (themMon/suaMon/huyMon); api-contract §3 UC04; BPC T4 | G21: Trung | H21: Đã nạp lại schema.sql rồi seed.sql; đã đăng nhập phucvu01; đơn dh-002 của ban-04 (B04) đang HOAN_THANH, gồm ct-003 (Cà phê sữa x2) và ct-004 (Trà đào x1) đều DA_XONG. | I21: ct-003 (thuộc dh-002) | J21: Cả hai: HTTP 409, maLoi=MON_DA_CHE_BIEN. Món vẫn DA_XONG; tongTien không đổi. | K21: Màn hình không cho phép thay đổi số lượng khi món đã xong | L21: Pass | M21: KQ-test\TC-04-10.png
A22: TC-04-11 | B22: UC04 | C22: Gọi thêm món đã hết nguyên liệu | D22: Alternative flow | E22: Black-box theo UC Spec (EF: món hết nguyên liệu) | F22: CD_CapNhat (themMon/suaMon/huyMon); api-contract §3 UC04 (MON_TAM_HET như UC01) | G22: Trung | H22: Đã nạp lại schema.sql rồi seed.sql; đã đăng nhập phucvu01; đơn dh-001 của ban-03 (B03) đang DANG_PHUC_VU, tổng 85.000: ct-001 (Cà phê sữa x2, DANG_LAM), ct-002 (Cà phê đen x1, CHO_PHA_CHE). mon-03 (Bạc xỉu) ở trạng thái TAM_HET. | I22: mon-03 (Bạc xỉu) x1 | J22: Giao diện: món hiện xám, không chọn được. API: HTTP 409, maLoi=MON_TAM_HET. Đơn không thay đổi. | K22: Giao diện: món hiện xám, không chọn được. | L22: Pass | M22: KQ-test\TC-04-11.png
A23: TC-04-12 | B23: UC04 | C23: Cập nhật đơn đã thanh toán bị chặn | D23: Alternative flow | E23: Black-box theo UC Spec (EF: đơn đã thanh toán) | F23: CD_CapNhat (themMon/suaMon/huyMon); api-contract §3 UC04; mã lỗi DON_DA_THANH_TOAN | G23: Trung | H23: Đã nạp lại schema.sql rồi seed.sql; đã đăng nhập phucvu01; dh-003 đã thanh toán. | I23: dh-003; mon-02 (Cà phê sữa) x1; chiTietId ct-005 | J23: Cả ba: HTTP 409, maLoi=DON_DA_THANH_TOAN. Đơn không thay đổi. | K23: Khi bàn đã thanh toán thì tự động chuyển sang cần dọn không cho phép thêm sửa xóa | L23: Pass | M23: KQ-test\TC-04-12.png
A24: TC-08-01 | B24: UC08 | C24: Lập hóa đơn bình thường | D24: Happy path | E24: Functional | F24: UC08 main flow | G24: Cao | H24: Bàn 01 có đơn, các món đã gửi bếp | I24: Bàn = 01 | J24: HTTP 200. Trả về HoaDonDTO: ds món, tổng tiền, giảm giá=0, cần thanh toán=tổng tiền. | L24: Chưa chạy
A25: TC-08-02 | B25: UC08 | C25: Lập hóa đơn cho bàn trống | D25: Negative | E25: EP | F25: UC08 exception | G25: Cao | H25: Bàn 02 chưa có khách (TRONG) | I25: Bàn = 02 | J25: HTTP 400, maloi=BAN_KHONG_CO_DON. Hệ thống chặn. | L25: Chưa chạy
A26: TC-08-03 | B26: UC08 | C26: Lập hóa đơn khi có món chưa gửi | D26: Negative | E26: Functional | F26: UC08 exception | G26: Cao | H26: Bàn 03 có món vừa chọn nhưng CHƯA gửi bếp | I26: Bàn = 03 | J26: HTTP 400, maloi=DON_CHUA_GUI_BEP. | L26: Chưa chạy
A27: TC-08-04 | B27: UC08 | C27: Lập hóa đơn có mã giảm giá | D27: Alternative flow | E27: Functional | F27: UC08 alt flow | G27: Trung | H27: Đơn hàng áp dụng khuyến mãi 10% | I27: giamGia=10 | J27: HTTP 200. HoaDonDTO tính chính xác: Cần thanh toán = Tổng tiền - Giảm giá. | L27: Chưa chạy
A28: TC-08-05 | B28: UC08 | C28: Lập hóa đơn giá trị cực lớn | D28: Boundary | E28: BVA | F28: UC08 boundary | G28: Thấp | H28: Bàn VIP gọi nhiều món | I28: Tổng > 10 triệu | J28: HTTP 200. Giao diện hiển thị không bị tràn, định dạng đúng tiền tệ (VNĐ). | L28: Chưa chạy
A29: TC-08-06 | B29: UC08 | C29: Hiển thị Popup xác nhận thanh toán | D29: Happy path | E29: Functional | F29: UC08 main flow | G29: Cao | H29: Đang xem hóa đơn hợp lệ | I29: N/A | J29: Popup thanh toán hiện ra với đúng tổng tiền cần thu từ HoaDonDTO. | L29: Chưa chạy
A30: TC-10-01 | B30: UC10 | C30: Thanh toán tiền mặt, khách đưa dư tiền (UC10.1) | D30: Happy path | E30: Functional (main flow) | F30: SD_ThanhToan; api-contract §3 UC10 (POST /payments); UC10.1 | G30: Cao | H30: Đã đăng nhập thungan01; đơn dh-002 (ban-04/B04, HOAN_THANH, tổng 100.000, mọi món DA_XONG) chưa thanh toán (vừa nạp lại DB). | I30: donHangId = dh-002; phuongThuc = TIEN_MAT; tienKhachDua = 100.000 + 10.000 = 110.000; maGiaoDich mới | J30: HTTP 200; thanhCong=true; soTienThanhToan=100.000; tienThoi=10.000; trangThaiDon=DA_THANH_TOAN; trangThaiBan=CAN_DON; daXuLyTruoc=false. CSDL: don_hang DA_THANH_TOAN, ban CAN_DON, đúng 1 bản ghi thanh_toan. Giao diện: đóng popup, hiện toast thành công. | K30: HTTP 200; thanhCong=true; soTienThanhToan=100.000; tienThoi=10.000; trangThaiDon=DA_THANH_TOAN; trangThaiBan=CAN_DON; daXuLyTruoc=false. CSDL: don_hang DA_THANH_TOAN, ban CAN_DON, đúng 1 bản ghi thanh_toan. Giao diện: đóng popup, hiện toast thành công. | L30: Pass | M30: KQ-test\TC-10-01.png | N30: Nạp lại schema.sql + seed.sql trước TC này (đơn dh-002 chỉ thanh toán được một lần).
A31: TC-10-02 | B31: UC10 | C31: Tiền khách đưa đúng bằng số cần trả (tiền thối 0) | D31: Boundary | E31: BVA (tienKhachDua = số cần trả) | F31: SD_ThanhToan; api-contract §3 UC10 (POST /payments); BPC T6 (tinhTienThoi) | G31: Cao | H31: Đã đăng nhập thungan01; đơn dh-001 (ban-03/B03, HOAN_THANH, tổng 85.000, mọi món DA_XONG) chưa thanh toán (vừa nạp lại DB). | I31: phuongThuc = TIEN_MAT; tienKhachDua = 85.000; maGiaoDich mới | J31: HTTP 200; thanhCong=true; tienThoi=0; trangThaiDon=DA_THANH_TOAN; trangThaiBan=CAN_DON. | K31: HTTP 200; thanhCong=true; tienThoi=0; trangThaiDon=DA_THANH_TOAN; trangThaiBan=CAN_DON. | L31: Pass | M31: KQ-test\TC-10-02.png | N31: Nạp lại schema.sql + seed.sql trước TC này (đơn dh-002 chỉ thanh toán được một lần).
A32: TC-10-03 | B32: UC10 | C32: Tiền khách đưa thiếu 1.000đ | D32: Boundary | E32: BVA (ngay dưới biên: số cần trả − 1.000) | F32: SD_ThanhToan; api-contract §3 UC10 (POST /payments); mã lỗi TIEN_KHONG_DU | G32: Cao | H32: Đã đăng nhập thungan01; đơn dh-002 (ban-04/B04, HOAN_THANH, tổng 100.000, mọi món DA_XONG) chưa thanh toán (vừa nạp lại DB). | I32: phuongThuc = TIEN_MAT; tienKhachDua = 100.000 − 1.000 = 99.000; maGiaoDich mới | J32: HTTP 400, maLoi=TIEN_KHONG_DU, thông báo "Số tiền khách đưa chưa đủ" hiện dưới ô nhập. Đơn vẫn DANG_PHUC_VU; bàn không đổi; không có bản ghi thanh_toan mới. | K32: HTTP 400, maLoi=TIEN_KHONG_DU, thông báo "Số tiền khách đưa chưa đủ" hiện dưới ô nhập. Đơn vẫn DANG_PHUC_VU; bàn không đổi; không có bản ghi thanh_toan mới. | L32: Pass | M32: KQ-test\TC-10-03.png
A33: TC-10-04 | B33: UC10 | C33: Tiền mặt nhưng thiếu tienKhachDua | D33: Negative | E33: EP (invalid class: thiếu trường bắt buộc) | F33: SD_ThanhToan; api-contract §3 UC10 (POST /payments) (tienKhachDua bắt buộc khi TIEN_MAT) | G33: Trung | H33: Đã đăng nhập thungan01; đơn dh-002 (ban-04/B04, HOAN_THANH, tổng 100.000, mọi món DA_XONG) chưa thanh toán (vừa nạp lại DB). | I33: phuongThuc = TIEN_MAT; không có tienKhachDua; maGiaoDich mới | J33: HTTP 400, maLoi=DU_LIEU_KHONG_HOP_LE. Không ghi dữ liệu nào. | L33: Chưa chạy | N33: Mã lỗi là giả định [X10].
A34: TC-10-05 | B34: UC10 | C34: Phương thức thanh toán không hợp lệ | D34: Negative | E34: EP (invalid class: phuongThuc ngoài tập cho phép) | F34: SD_ThanhToan; api-contract §3 UC10 (POST /payments); mã lỗi PHUONG_THUC_KHONG_HOP_LE | G34: Trung | H34: Đã đăng nhập thungan01; đơn dh-002 (ban-04/B04, HOAN_THANH, tổng 100.000, mọi món DA_XONG) chưa thanh toán (vừa nạp lại DB). | I34: phuongThuc = "THE_TIN_DUNG"; maGiaoDich mới | J34: HTTP 400, maLoi=PHUONG_THUC_KHONG_HOP_LE. Không ghi dữ liệu nào. | L34: Chưa chạy
A35: TC-10-06 | B35: UC10 | C35: Thanh toán QR giả lập (UC10.2) | D35: Happy path | E35: Functional (UC10.2) | F35: SD_ThanhToan; api-contract §3 UC10 (POST /payments); UC10.2 | G35: Cao | H35: Đã đăng nhập thungan01; đơn dh-002 (ban-04/B04, HOAN_THANH, tổng 100.000, mọi món DA_XONG) chưa thanh toán (vừa nạp lại DB). | I35: donHangId = dh-002; phuongThuc = QR; không gửi tienKhachDua; maGiaoDich mới | J35: HTTP 200; thanhCong=true; phuongThuc=QR; trả về maGiaoDich; soTienThanhToan=100.000; trangThaiDon=DA_THANH_TOAN; trangThaiBan=CAN_DON. Không yêu cầu nhập tiền khách đưa. | K35: HTTP 200; thanhCong=true; phuongThuc=QR; trả về maGiaoDich; soTienThanhToan=100.000; trangThaiDon=DA_THANH_TOAN; trangThaiBan=CAN_DON. Không yêu cầu nhập tiền khách đưa. | L35: Pass | M35: KQ-test\TC-10-06.png | N35: Giá trị tienThoi với QR (0 hay null) chưa rõ [X10]. Nạp lại schema.sql + seed.sql trước TC này (đơn dh-002 chỉ thanh toán được một lần).
A36: TC-10-07 | B36: UC10 | C36: Thanh toán đơn đã thanh toán (mã giao dịch khác) | D36: Alternative flow | E36: Black-box theo UC Spec (EF: đơn đã thanh toán) | F36: SD_ThanhToan; api-contract §3 UC10 (POST /payments); mã lỗi DON_DA_THANH_TOAN | G36: Cao | H36: Đã đăng nhập thungan01; dh-003 đã thanh toán. | I36: donHangId = dh-003; phuongThuc = TIEN_MAT; tienKhachDua đủ; maGiaoDich mới (mã đã dùng trong seed: GD-20261008-001) | J36: HTTP 409, maLoi=DON_DA_THANH_TOAN. Không thêm bản ghi thanh_toan; đơn và bàn giữ nguyên. | K36: đơn đã thanh toán thì hệ thống sẽ không hiện nữa | L36: Pass | M36: KQ-test\TC-10-07.png
A37: TC-10-8 | B37: UC10 | C37: Lỗi giữa chừng: rollback cả 3 thao tác ghi | D37: Alternative flow | E37: Black-box theo UC Spec (EF: lỗi hệ thống) | F37: SD_ThanhToan; api-contract §3 UC10 (POST /payments); BPC T6 (3 thao tác ghi trong 1 transaction) | G37: Cao | H37: Đã đăng nhập thungan01; đơn dh-002 (ban-04/B04, HOAN_THANH, tổng 100.000, mọi món DA_XONG) chưa thanh toán (vừa nạp lại DB). Có cách ép một trong 3 thao tác ghi bị lỗi (cách làm do Tuấn xác nhận). | I37: donHangId = dh-002; phuongThuc = TIEN_MAT; tienKhachDua = 100.000 | J37: API trả lỗi (giả định HTTP 500, maLoi=LOI_HE_THONG). Rollback toàn bộ: không có bản ghi thanh_toan mới; đơn vẫn DANG_PHUC_VU; bàn vẫn DANG_PHUC_VU (không có dữ liệu nửa vời). | L37: Chưa chạy | N37: Cách ép lỗi [X07]. Nạp lại schema.sql + seed.sql trước TC này (đơn dh-002 chỉ thanh toán được một lần).
A38: TC-10-09 | B38: UC10 | C38: Nút "Xác nhận" bị khóa khi đang xử lý (chống bấm 2 lần) | D38: Phi chức năng | E38: UI: chống thao tác trùng | F38: BPC H4 (khóa nút khi đang xử lý; maGiaoDich tạo 1 lần mỗi lượt) | G38: Trung | H38: Đã đăng nhập thungan01; đơn dh-002 (ban-04/B04, HOAN_THANH, tổng 100.000, mọi món DA_XONG) chưa thanh toán (vừa nạp lại DB). | I38: phuongThuc = TIEN_MAT; tienKhachDua = 100.000 | J38: Nút bị khóa ngay khi đang xử lý; chỉ 1 request POST /api/payments được gửi (nếu có 2 thì cùng maGiaoDich). CSDL chỉ có 1 bản ghi thanh_toan. Popup đóng, giỏ được xóa, hiện toast thành công. | L38: Chưa chạy | N38: Tên nút theo giao diện của Hậu, cập nhật khi nhận bản 07/10 [X14]. Nạp lại schema.sql + seed.sql trước TC này (đơn dh-002 chỉ thanh toán được một lần).
A39: TC-15-01 | B39: UC15 | C39: Hiển thị đúng thứ tự FIFO | D39: Happy path | E39: Functional | F39: UC15 main flow | G39: Cao | H39: Đã chạy reset_db | I39: 3 Order gửi cách nhau 1 phút | J39: HTTP 200. Màn hình KDS hiển thị 3 thẻ Order xếp đúng thứ tự FIFO (Order A trên cùng). | L39: Chưa chạy
A40: TC-15-02 | B40: UC15 | C40: Hiển thị trạng thái màn hình rỗng | D40: Alternative flow | E40: Functional | F40: UC15 alt flow | G40: Thấp | H40: Quán chưa có order nào | I40: N/A | J40: HTTP 200. Danh sách rỗng, giao diện hiện trạng thái "Chưa có order". | L40: Chưa chạy
...

Sheet Bug Report
A1: Bug ID | B1: Related TC | C1: Mô tả lỗi | D1: Bước tái hiện | E1: Kết quả thực tế | F1: Kết quả mong đợi | G1: Mức độ nghiêm trọng | H1: Người sửa | I1: Trạng thái | J1: Kết quả retest

Sheet Tổng hợp
A1: TỔNG HỢP KẾT QUẢ KIỂM THỬ
A3: UC | B3: Tên UC | C3: Người test | D3: Tổng TC | E3: Đã chạy | F3: PASS | G3: FAIL | H3: Chưa chạy | I3: Tỉ lệ pass (%) | J3: Số bug
A4: UC21 | B4: Đăng nhập hệ thống | C4: Kiệt | D4: =COUNTIF('Test Case'!$B:$B,$A4) -> 11 | E4: =F4+G4 -> 11 | F4: =COUNTIFS('Test Case'!$B:$B,$A4,'Test Case'!$L:$L,"PASS") -> 11 | G4: =COUNTIFS('Test Case'!$B:$B,$A4,'Test Case'!$L:$L,"FAIL") -> 0 | H4: =D4-E4 -> 0 | I4: =IF(E4=0,"-",F4/E4) -> 1 | J4: =COUNTIFS('Bug Report'!$A:$A,"BUG-N5-*",'Bug Report'!$B:$B,"TC-"&RIGHT($A4,2)&"-*") -> 0
A5: UC01 | B5: Tạo và gửi order | C5: Kiệt | D5: =COUNTIF('Test Case'!$B:$B,$A5) -> 10 | E5: =F5+G5 -> 10 | F5: =COUNTIFS('Test Case'!$B:$B,$A5,'Test Case'!$L:$L,"PASS") -> 10 | G5: =COUNTIFS('Test Case'!$B:$B,$A5,'Test Case'!$L:$L,"FAIL") -> 0 | H5: =D5-E5 -> 0 | I5: =IF(E5=0,"-",F5/E5) -> 1 | J5: =COUNTIFS('Bug Report'!$A:$A,"BUG-N5-*",'Bug Report'!$B:$B,"TC-"&RIGHT($A5,2)&"-*") -> 0
A6: UC04 | B6: Cập nhật order (gọi thêm, sửa, hủy món) | C6: Kiệt | D6: =COUNTIF('Test Case'!$B:$B,$A6) -> 12 | E6: =F6+G6 -> 12 | F6: =COUNTIFS('Test Case'!$B:$B,$A6,'Test Case'!$L:$L,"PASS") -> 12 | G6: =COUNTIFS('Test Case'!$B:$B,$A6,'Test Case'!$L:$L,"FAIL") -> 0 | H6: =D6-E6 -> 0 | I6: =IF(E6=0,"-",F6/E6) -> 1 | J6: =COUNTIFS('Bug Report'!$A:$A,"BUG-N5-*",'Bug Report'!$B:$B,"TC-"&RIGHT($A6,2)&"-*") -> 0
A7: UC10 | B7: Thanh toán hóa đơn (UC10.1 tiền mặt, UC10.2 QR giả lập) | C7: Kiệt | D7: =COUNTIF('Test Case'!$B:$B,$A7) -> 9 | E7: =F7+G7 -> 5 | F7: =COUNTIFS('Test Case'!$B:$B,$A7,'Test Case'!$L:$L,"PASS") -> 5 | G7: =COUNTIFS('Test Case'!$B:$B,$A7,'Test Case'!$L:$L,"FAIL") -> 0 | H7: =D7-E7 -> 4 | I7: =IF(E7=0,"-",F7/E7) -> 1 | J7: =COUNTIFS('Bug Report'!$A:$A,"BUG-N5-*",'Bug Report'!$B:$B,"TC-"&RIGHT($A7,2)&"-*") -> 0
A8: UC15 | B8: Hiển thị danh sách đơn hàng (KDS) | C8: Duy | D8: =COUNTIF('Test Case'!$B:$B,$A8) -> 5 | E8: =F8+G8 -> 0 | F8: =COUNTIFS('Test Case'!$B:$B,$A8,'Test Case'!$L:$L,"PASS") -> 0 | G8: =COUNTIFS('Test Case'!$B:$B,$A8,'Test Case'!$L:$L,"FAIL") -> 0 | H8: =D8-E8 -> 5 | I8: =IF(E8=0,"-",F8/E8) -> - | J8: =COUNTIFS('Bug Report'!$A:$A,"BUG-N5-*",'Bug Report'!$B:$B,"TC-"&RIGHT($A8,2)&"-*") -> 0
A9: UC16 | B9: Cập nhật trạng thái chế biến | C9: Duy | D9: =COUNTIF('Test Case'!$B:$B,$A9) -> 6 | E9: =F9+G9 -> 0 | F9: =COUNTIFS('Test Case'!$B:$B,$A9,'Test Case'!$L:$L,"PASS") -> 0 | G9: =COUNTIFS('Test Case'!$B:$B,$A9,'Test Case'!$L:$L,"FAIL") -> 0 | H9: =D9-E9 -> 6 | I9: =IF(E9=0,"-",F9/E9) -> - | J9: =COUNTIFS('Bug Report'!$A:$A,"BUG-N5-*",'Bug Report'!$B:$B,"TC-"&RIGHT($A9,2)&"-*") -> 0
A10: UC18 | B10: Đánh dấu hết nguyên liệu | C10: Duy | D10: =COUNTIF('Test Case'!$B:$B,$A10) -> 5 | E10: =F10+G10 -> 0 | F10: =COUNTIFS('Test Case'!$B:$B,$A10,'Test Case'!$L:$L,"PASS") -> 0 | G10: =COUNTIFS('Test Case'!$B:$B,$A10,'Test Case'!$L:$L,"FAIL") -> 0 | H10: =D10-E10 -> 5 | I10: =IF(E10=0,"-",F10/E10) -> - | J10: =COUNTIFS('Bug Report'!$A:$A,"BUG-N5-*",'Bug Report'!$B:$B,"TC-"&RIGHT($A10,2)&"-*") -> 0
A11: UC08 | B11: Lập hóa đơn | C11: Duy | D11: =COUNTIF('Test Case'!$B:$B,$A11) -> 6 | E11: =F11+G11 -> 0 | F11: =COUNTIFS('Test Case'!$B:$B,$A11,'Test Case'!$L:$L,"PASS") -> 0 | G11: =COUNTIFS('Test Case'!$B:$B,$A11,'Test Case'!$L:$L,"FAIL") -> 0 | H11: =D11-E11 -> 6 | I11: =IF(E11=0,"-",F11/E11) -> - | J11: =COUNTIFS('Bug Report'!$A:$A,"BUG-N5-*",'Bug Report'!$B:$B,"TC-"&RIGHT($A11,2)&"-*") -> 0
A12: TỔNG | B12: Toàn nhóm (8 UC) | D12: =SUM(D4:D11) -> 64 | E12: =SUM(E4:E11) -> 38 | F12: =SUM(F4:F11) -> 38 | G12: =SUM(G4:G11) -> 0 | H12: =SUM(H4:H11) -> 26 | I12: =IF(E12=0,"-",F12/E12) -> 1 | J12: =SUM(J4:J11) -> 0
A14: 1. Theo loại test case
A15: Loại | D15: Tổng TC | E15: PASS | F15: FAIL
A16: Happy path | D16: =COUNTIF('Test Case'!$D:$D,$A16) -> 19 | E16: =COUNTIFS('Test Case'!$D:$D,$A16,'Test Case'!$L:$L,"PASS") -> 10 | F16: =COUNTIFS('Test Case'!$D:$D,$A16,'Test Case'!$L:$L,"FAIL") -> 0
A17: Negative | D17: =COUNTIF('Test Case'!$D:$D,$A17) -> 28 | E17: =COUNTIFS('Test Case'!$D:$D,$A17,'Test Case'!$L:$L,"PASS") -> 10 | F17: =COUNTIFS('Test Case'!$D:$D,$A17,'Test Case'!$L:$L,"FAIL") -> 0
A18: Boundary | D18: =COUNTIF('Test Case'!$D:$D,$A18) -> 16 | E18: =COUNTIFS('Test Case'!$D:$D,$A18,'Test Case'!$L:$L,"PASS") -> 12 | F18: =COUNTIFS('Test Case'!$D:$D,$A18,'Test Case'!$L:$L,"FAIL") -> 0
A19: Alternative flow | D19: =COUNTIF('Test Case'!$D:$D,$A19) -> 24 | E19: =COUNTIFS('Test Case'!$D:$D,$A19,'Test Case'!$L:$L,"PASS") -> 12 | F19: =COUNTIFS('Test Case'!$D:$D,$A19,'Test Case'!$L:$L,"FAIL") -> 0
A20: Phi chức năng | D20: =COUNTIF('Test Case'!$D:$D,$A20) -> 1 | E20: =COUNTIFS('Test Case'!$D:$D,$A20,'Test Case'!$L:$L,"PASS") -> 0 | F20: =COUNTIFS('Test Case'!$D:$D,$A20,'Test Case'!$L:$L,"FAIL") -> 0
A23: 2. Bug theo mức độ nghiêm trọng
A24: Mức độ | D24: Số bug | E24: Đã sửa | F24: Chưa sửa
A25: Critical | D25: =COUNTIFS('Bug Report'!$A:$A,"BUG-N5-*",'Bug Report'!$G:$G,$A25) -> 0 | E25: =COUNTIFS('Bug Report'!$A:$A,"BUG-N5-*",'Bug Report'!$G:$G,$A25,'Bug Report'!$I:$I,"Đã retest đạt") -> 0 | F25: =D25-E25 -> 0
A26: High | D26: =COUNTIFS('Bug Report'!$A:$A,"BUG-N5-*",'Bug Report'!$G:$G,$A26) -> 0 | E26: =COUNTIFS('Bug Report'!$A:$A,"BUG-N5-*",'Bug Report'!$G:$G,$A26,'Bug Report'!$I:$I,"Đã retest đạt") -> 0 | F26: =D26-E26 -> 0
A27: Medium | D27: =COUNTIFS('Bug Report'!$A:$A,"BUG-N5-*",'Bug Report'!$G:$G,$A27) -> 0 | E27: =COUNTIFS('Bug Report'!$A:$A,"BUG-N5-*",'Bug Report'!$G:$G,$A27,'Bug Report'!$I:$I,"Đã retest đạt") -> 0 | F27: =D27-E27 -> 0
A28: Low | D28: =COUNTIFS('Bug Report'!$A:$A,"BUG-N5-*",'Bug Report'!$G:$G,$A28) -> 0 | E28: =COUNTIFS('Bug Report'!$A:$A,"BUG-N5-*",'Bug Report'!$G:$G,$A28,'Bug Report'!$I:$I,"Đã retest đạt") -> 0 | F28: =D28-E28 -> 0
A30: 3. Khung báo cáo kết quả (mẫu C6-D2), điền ở K4 trước 21:00 09/10
A31: Tổng hợp số liệu | B31: ="Đã chạy "&E12&" / "&D12&" TC; PASS "&F12&"; FAIL "&G12&"; tỉ lệ pass "&IF(E12=0,"-",TEXT(F12/E12,"0.0%")) -> Đã chạy 38 / 64 TC; PASS 38; FAIL 0; tỉ lệ pass 100.0%
A32: Lỗi nghiêm trọng nhất
A33: Phân tích nguyên nhân
A34: Hướng sửa (method / file)
A35: Nhận xét về độ bao phủ
